<?xml version="1.0" ?>
<robot name="vitirover" xmlns:xacro="http://www.ros.org/wiki/xacro">
  <!-- ros_control plugin -->
  <gazebo>
    <plugin name="gazebo_ros_control" filename="libgazebo_ros_control.so">
      <robotNamespace>/vitirover</robotNamespace>
    </plugin>
  </gazebo>
  
  <!-- Wheels -->
  <!-- in kg-->
  <!-- Defining the colors used in this robot -->
  <material name="Black">
    <color rgba="0.0 0.0 0.0 1.0"/>
  </material>
  <material name="Red">
    <color rgba="0.8 0.0 0.0 1.0"/>
  </material>
  <material name="White">
    <color rgba="1.0 1.0 1.0 1.0"/>
  </material>
  <material name="Blue">
    <color rgba="0.0 0.0 0.8 1.0"/>
  </material>
  <material name="DarkGrey">
  <color rgba="0.2 0.2 0.2 1.0"/>
  </material>
  <material name="Yellow">
    <color rgba="1.0 1.0 0.0 1.0"/>
  </material>

  <!-- PROPERTY LIST -->
  <!--All units in m-kg-s-radians unit system -->
  <!-- Wheels -->
  <!-- in kg-->
  <!-- BASE-FOOTPRINT -->
  <!-- base_footprint is a fictitious link(frame) that is on the ground right below base_link origin -->
  <link name="base_footprint"/>
  <gazebo reference="base_footprint">
    <material>Gazebo/DarkGrey</material>
  </gazebo>
  <joint name="base_footprint_joint" type="fixed">
    <origin rpy="0 0 0" xyz="0 0 0.1"/>
    <parent link="base_footprint"/>
    <child link="base_link"/>
  </joint>
  <!-- BASE-LINK -->
  <!--Actual body/chassis of the robot-->
  <link name="base_link">
    <inertial>
      <mass value="25"/>
      <origin  rpy="1.57079632679 3.141592653599265359 1.57079632679" xyz="0 0 0.05"/>
      <!--The 3x3 rotational inertia matrix. -->
      <inertia ixx="1.1927083" ixy="0" ixz="0" iyy="1.427083" iyz="0" izz="0.27604167"/>
    </inertial>
    <visual>
      <origin  rpy="3.14159265359 0.0 4.71238898038" xyz="0 0 0.2"/>
      <geometry>
        <mesh filename="package://mobile_robot/meshes/chassis.stl" scale="10 10 10"/>
      </geometry>
      <material name="Yellow"/>
    </visual>
    <collision>
      <origin  rpy="3.14159265359 0.0 4.71238898038" xyz="0 0 0.15"/>
      <geometry>
        <box size="0.4 0.8 0.1"/>
      </geometry>
    </collision>
  </link>

  <gazebo reference="base_link">
    <material>Gazebo/Yellow</material> <!-- Change material to "Gazebo/Yellow" -->
    <turnGravityOff>false</turnGravityOff>
  </gazebo>

  <!-- FRONT -->
  <!-- Right -->
  <link name="front_right_wheel">
    <inertial>
      <mass value="2.5"/>
      <origin rpy="1.57079632679 0  0 " xyz="0 0 0"/>
      <inertia ixx="0.00536083" ixy="0" ixz="0" iyy="0.00536083" iyz="0" izz="0.009680"/>
    </inertial>
    
    <visual>
      <origin rpy="1.57079632679 0  0 " xyz="0 0 0"/>
      <geometry>
        <cylinder length="0.05" radius="0.088"/>
      </geometry>
      <material name="DarkGrey"/>
    </visual>

    <collision>
      <origin rpy="1.57079632679 0 0 " xyz="0 0 0"/>
      <geometry>
        <cylinder length="0.05" radius="0.088"/>
      </geometry>
      <surface>
        <friction>
          <ode>
            <mu>1.0</mu>
            <mu2>1.0</mu2>
          </ode>
        </friction>
        <contact>
          <ode>
            <soft_cfm>0.01</soft_cfm>   <!-- Soft constraint force mixing -->
            <soft_erp>0.8</soft_erp>     <!-- Error reduction parameter -->
            <kp>1000000.0</kp>           <!-- Contact stiffness -->
            <kd>1.0</kd>                 <!-- Contact damping -->
          </ode>
        </contact>
      </surface>
    </collision>
  </link>

  <gazebo reference="front_right_wheel">
    <mu1 value="1.0"/>
    <mu2 value="1.0"/>
    <kp value="10000000.0"/>
    <kd value="1000.0"/>
    <fdir1 value="1 0 0"/>
    <material>Gazebo/DarkGrey</material>
    <turnGravityOff>false</turnGravityOff>
  </gazebo>

  <joint name="front_right_wheel_joint" type="continuous">
    <parent link="base_link"/>
    <child link="front_right_wheel"/>
    <origin rpy="0 0 0" xyz="0.2 0.1875 0.0"/>
    <axis rpy="0 0 0" xyz="0 1 0"/>
    <limit effort="100" velocity="100"/>
    <joint_properties  damping="0.3" friction="0.1"/>
  </joint>

  <!-- Transmission is important to link the joints and the controller -->
  <transmission name="front_right_wheel_joint_trans">
    <type>transmission_interface/SimpleTransmission</type>
    <joint name="front_right_wheel_joint">
      <hardwareInterface>hardware_interface/VelocityJointInterface</hardwareInterface>
    </joint>
    <actuator name="front_right_wheel_joint_motor">
      <hardwareInterface>hardware_interface/VelocityJointInterface</hardwareInterface>
      <mechanicalReduction>1</mechanicalReduction>
    </actuator>
  </transmission>


  <!-- Left -->
  <link name="front_left_wheel">
    <inertial>
      <mass value="2.5"/>
      <origin rpy="1.57079632679 0  0 " xyz="0 0 0"/>
      <inertia ixx="0.00536083" ixy="0" ixz="0" iyy="0.00536083" iyz="0" izz="0.009680"/>
    </inertial>
    
    <visual>
      <origin rpy="1.57079632679 0  0 " xyz="0 0 0"/>
      <geometry>
        <cylinder length="0.05" radius="0.088"/>
      </geometry>
      <material name="DarkGrey"/>
    </visual>

    <collision>
      <origin rpy="1.57079632679 0 0 " xyz="0 0 0"/>
      <geometry>
        <cylinder length="0.05" radius="0.088"/>
      </geometry>
      <surface>
        <friction>
          <ode>
            <mu>1.0</mu>
            <mu2>1.0</mu2>
          </ode>
        </friction>
        <contact>
          <ode>
            <soft_cfm>0.01</soft_cfm>   <!-- Soft constraint force mixing -->
            <soft_erp>0.8</soft_erp>     <!-- Error reduction parameter -->
            <kp>1000000.0</kp>           <!-- Contact stiffness -->
            <kd>1.0</kd>                 <!-- Contact damping -->
          </ode>
        </contact>
      </surface>
    </collision>
  </link>

  <gazebo reference="front_left_wheel">
    <mu1 value="1.0"/>
    <mu2 value="1.0"/>
    <kp value="10000000.0"/>
    <kd value="1000.0"/>
    <fdir1 value="1 0 0"/>
    <material>Gazebo/DarkGrey</material>
    <turnGravityOff>false</turnGravityOff>
  </gazebo>

  <joint name="front_left_wheel_joint" type="continuous">
    <parent link="base_link"/>
    <child link="front_left_wheel"/>
    <origin rpy="0 0 0" xyz="0.2 -0.1875 0.0"/>
    <axis rpy="0 0 0" xyz="0 1 0"/>
    <limit effort="100" velocity="100"/>
    <joint_properties  damping="0.3" friction="0.1"/>
  </joint>
  <!-- Transmission is important to link the joints and the controller -->
  <transmission name="front_left_wheel_joint_trans">
    <type>transmission_interface/SimpleTransmission</type>
    <joint name="front_left_wheel_joint">
      <hardwareInterface>hardware_interface/VelocityJointInterface</hardwareInterface>
    </joint>
    <actuator name="front_left_wheel_joint_motor">
      <hardwareInterface>hardware_interface/VelocityJointInterface</hardwareInterface>
      <mechanicalReduction>1</mechanicalReduction>
    </actuator>
  </transmission>

  <!-- REAR -->
  <!-- Right -->
  <link name="rear_right_wheel">
    <inertial>
      <mass value="2.5"/>
      <origin rpy="1.57079632679 0  0 " xyz="0 0 0"/>
      <inertia ixx="0.00536083" ixy="0" ixz="0" iyy="0.00536083" iyz="0" izz="0.009680"/>
    </inertial>
    
    <visual>
      <origin rpy="1.57079632679 0  0 " xyz="0 0 0"/>
      <geometry>
        <cylinder length="0.05" radius="0.088"/>
      </geometry>
      <material name="DarkGrey"/>
    </visual>

    <collision>
      <origin rpy="1.57079632679 0 0 " xyz="0 0 0"/>
      <geometry>
        <cylinder length="0.05" radius="0.088"/>
      </geometry>
      <surface>
        <friction>
          <ode>
            <mu>1.0</mu>
            <mu2>1.0</mu2>
          </ode>
        </friction>
        <contact>
          <ode>
            <soft_cfm>0.01</soft_cfm>   <!-- Soft constraint force mixing -->
            <soft_erp>0.8</soft_erp>     <!-- Error reduction parameter -->
            <kp>1000000.0</kp>           <!-- Contact stiffness -->
            <kd>1.0</kd>                 <!-- Contact damping -->
          </ode>
        </contact>
      </surface>
    </collision>
  </link>

  <gazebo reference="rear_right_wheel">
    <mu1 value="1.0"/>
    <mu2 value="1.0"/>
    <kp value="10000000.0"/>
    <kd value="1000.0"/>
    <fdir1 value="1 0 0"/>
    <material>Gazebo/DarkGrey</material>
    <turnGravityOff>false</turnGravityOff>
  </gazebo>

  <!-- Left -->
  <link name="rear_left_wheel">
    <inertial>
      <mass value="2.5"/>
      <origin rpy="1.57079632679 0  0 " xyz="0 0 0"/>
      <inertia ixx="0.00536083" ixy="0" ixz="0" iyy="0.00536083" iyz="0" izz="0.009680"/>
    </inertial>
    
    <visual>
      <origin rpy="1.57079632679 0  0 " xyz="0 0 0"/>
      <geometry>
        <cylinder length="0.05" radius="0.088"/>
      </geometry>
      <material name="DarkGrey"/>
    </visual>

    <collision>
      <origin rpy="1.57079632679 0 0 " xyz="0 0 0"/>
      <geometry>
        <cylinder length="0.05" radius="0.088"/>
      </geometry>
      <surface>
        <friction>
          <ode>
            <mu>1.0</mu>
            <mu2>1.0</mu2>
          </ode>
        </friction>
        <contact>
          <ode>
            <soft_cfm>0.01</soft_cfm>   <!-- Soft constraint force mixing -->
            <soft_erp>0.8</soft_erp>     <!-- Error reduction parameter -->
            <kp>1000000.0</kp>           <!-- Contact stiffness -->
            <kd>1.0</kd>                 <!-- Contact damping -->
          </ode>
        </contact>
      </surface>
    </collision>
  </link>

  <gazebo reference="rear_left_wheel">
    <mu1 value="1.0"/>
    <mu2 value="1.0"/>
    <kp value="10000000.0"/>
    <kd value="1000.0"/>
    <fdir1 value="1 0 0"/>
    <material>Gazebo/DarkGrey</material>
    <turnGravityOff>false</turnGravityOff>
  </gazebo>

<!-- FRONT AXLE -->
<link name="front_axle">
  <visual>
    <origin rpy="0 0 0" xyz="0 0 0"/>
    <geometry>
      <cylinder length="0.35" radius="0.02"/>
    </geometry>
    <material name="DarkGrey"/>
  </visual>

  <collision>
    <origin rpy="0 0 0" xyz="0 0 0"/>
    <geometry>
      <cylinder length="0.35" radius="0.02"/>
    </geometry>
    <surface>
        <friction>
          <ode>
            <mu>1.0</mu>
            <mu2>1.0</mu2>
          </ode>
        </friction>
    </surface>
  </collision>

  <inertial>
    <mass value="1"/>
    <origin rpy="0 0 0" xyz="0 0 0"/>
    <inertia ixx="0.0134" ixy="0.0" ixz="0.0" iyy="0.0134" iyz="0.0" izz="0.0002"/>
  </inertial>
</link>

<!-- FRONT AXLE JOINT -->
<joint name="front_axle_joint" type="fixed">
  <origin rpy="4.7124 0 0" xyz="0.2 0 0"/>
  <axis xyz="0 1 0" rpy="0 0 0" /> 
  <parent link="base_link"/>
  <child link="front_axle"/>
</joint>


<!-- REAR AXLE -->
<link name="rear_axle">
  <visual>
    <origin rpy="0 0 0" xyz="0 0 0"/>
    <geometry>
      <cylinder length="0.35" radius="0.02"/>
    </geometry>
    <material name="DarkGrey"/>
  </visual>

  <collision>
    <origin rpy="0 0 0" xyz="0 0 0"/>
    <geometry>
      <cylinder length="0.35" radius="0.02"/>
    </geometry>
    <surface>
        <friction>
          <ode>
            <mu>1.0</mu>
            <mu2>1.0</mu2>
          </ode>
        </friction>
    </surface>
  </collision>

  <inertial>
    <mass value="1"/>
    <origin rpy="0 0 0" xyz="0 0 0"/>
    <inertia ixx="0.0103083" ixy="0.0" ixz="0.0" iyy="0.0103083" iyz="0.0" izz="0.0002"/>
  </inertial>
</link>

<!-- REAR AXLE JOINT -->
<joint name="rear_axle_joint" type="revolute">
  <origin rpy="4.7124 0 0" xyz="-0.2 0 0"/>
  <axis xyz="0 1 0" rpy="0 0 0" /> 
  <parent link="base_link"/>
  <child link="rear_axle"/>
  <limit effort="100" velocity="100" lower="-0.3142" upper="0.3142"/> <!-- radians -->
  <joint_properties damping="0.5" friction="0.1"/>
</joint>


<!-- Transmission is important to link the joints and the controller -->
<transmission name="rear_axle_joint_trans">
  <type>transmission_interface/SimpleTransmission</type>
  <joint name="rear_axle_joint">
    <hardwareInterface>hardware_interface/EffortJointInterface</hardwareInterface>
  </joint>
  <actuator name="rear_axle_joint_motor">
    <hardwareInterface>hardware_interface/EffortJointInterface</hardwareInterface>
    <mechanicalReduction>1</mechanicalReduction>
  </actuator>
</transmission>

<!-- REAR WHEELS LINKING TO AXLE -->

  <joint name="rear_left_wheel_axle_joint" type="continuous">
    <parent link="rear_axle"/>
    <child link="rear_left_wheel"/>
    <origin rpy="1.570796 0 0" xyz="0 0 -0.1875"/>
    <axis rpy="0 0 0" xyz="0 1 0"/>
    <limit effort="100" velocity="100"/>
    <joint_properties  damping="0.3" friction="0.1"/>
  </joint>

<!-- Transmission is important to link the joints and the controller -->
<transmission name="rear_left_wheel_joint_trans">
  <type>transmission_interface/SimpleTransmission</type>
  <joint name="rear_left_wheel_axle_joint">
    <hardwareInterface>hardware_interface/VelocityJointInterface</hardwareInterface>
  </joint>
  <actuator name="rear_left_wheel_joint_motor">
    <hardwareInterface>hardware_interface/VelocityJointInterface</hardwareInterface>
    <mechanicalReduction>1</mechanicalReduction>
  </actuator>
</transmission>

  <joint name="rear_right_wheel_axle_joint" type="continuous">
    <parent link="rear_axle"/>
    <child link="rear_right_wheel"/>
    <origin rpy="1.570796 0 0" xyz="0 0 0.1875"/>
    <axis rpy="0 0 0" xyz="0 1 0"/>
    <limit effort="100" velocity="100"/>
    <joint_properties  damping="0.3" friction="0.1"/>
  </joint>

<!-- Transmission is important to link the joints and the controller -->
<transmission name="rear_right_wheel_joint_trans">
  <type>transmission_interface/SimpleTransmission</type>
  <joint name="rear_right_wheel_axle_joint">
    <hardwareInterface>hardware_interface/VelocityJointInterface</hardwareInterface>
  </joint>
  <actuator name="rear_right_wheel_joint_motor">
    <hardwareInterface>hardware_interface/VelocityJointInterface</hardwareInterface>
    <mechanicalReduction>1</mechanicalReduction>
  </actuator>
</transmission>

</robot>
